<?xml version="1.0" encoding="UTF-8"?>
<!-- Generated by org.testng.reporters.JUnitReportReporter -->
<testsuite hostname="acer-53" failures="1" tests="1" name="Week5.HomeWork.MoveZeros" time="0.076" errors="0" timestamp="2023-09-16T13:21:00 IST" skipped="0">
  <testcase classname="Week5.HomeWork.MoveZeros" name="test" time="0.076">
    <failure message="arrays first differed at element [0]; expected:&lt;0&gt; but was:&lt;1&gt;" type="org.junit.internal.ArrayComparisonFailure">
      <![CDATA[arrays first differed at element [0]; expected:<0> but was:<1>
at org.junit.internal.ComparisonCriteria.arrayEquals(ComparisonCriteria.java:78)
at org.junit.internal.ComparisonCriteria.arrayEquals(ComparisonCriteria.java:28)
at org.junit.Assert.internalArrayEquals(Assert.java:534)
at org.junit.Assert.assertArrayEquals(Assert.java:418)
at org.junit.Assert.assertArrayEquals(Assert.java:429)
at Week5.HomeWork.MoveZeros.test(MoveZeros.java:28)
at java.base/jdk.internal.reflect.NativeMethodAccessorImpl.invoke0(Native Method)
at java.base/jdk.internal.reflect.NativeMethodAccessorImpl.invoke(NativeMethodAccessorImpl.java:78)
at java.base/jdk.internal.reflect.DelegatingMethodAccessorImpl.invoke(DelegatingMethodAccessorImpl.java:43)
at java.base/java.lang.reflect.Method.invoke(Method.java:567)
at org.testng.internal.MethodInvocationHelper.invokeMethod(MethodInvocationHelper.java:133)
at org.testng.internal.TestInvoker.invokeMethod(TestInvoker.java:598)
at org.testng.internal.TestInvoker.invokeTestMethod(TestInvoker.java:173)
at org.testng.internal.MethodRunner.runInSequence(MethodRunner.java:46)
at org.testng.internal.TestInvoker$MethodInvocationAgent.invoke(TestInvoker.java:824)
at org.testng.internal.TestInvoker.invokeTestMethods(TestInvoker.java:146)
at org.testng.internal.TestMethodWorker.invokeTestMethods(TestMethodWorker.java:146)
at org.testng.internal.TestMethodWorker.run(TestMethodWorker.java:128)
at java.base/java.util.ArrayList.forEach(ArrayList.java:1511)
at org.testng.TestRunner.privateRun(TestRunner.java:794)
at org.testng.TestRunner.run(TestRunner.java:596)
at org.testng.SuiteRunner.runTest(SuiteRunner.java:377)
at org.testng.SuiteRunner.runSequentially(SuiteRunner.java:371)
at org.testng.SuiteRunner.privateRun(SuiteRunner.java:332)
at org.testng.SuiteRunner.run(SuiteRunner.java:276)
at org.testng.SuiteRunnerWorker.runSuite(SuiteRunnerWorker.java:53)
at org.testng.SuiteRunnerWorker.run(SuiteRunnerWorker.java:96)
at org.testng.TestNG.runSuitesSequentially(TestNG.java:1212)
at org.testng.TestNG.runSuitesLocally(TestNG.java:1134)
at org.testng.TestNG.runSuites(TestNG.java:1063)
at org.testng.TestNG.run(TestNG.java:1031)
at org.testng.remote.AbstractRemoteTestNG.run(AbstractRemoteTestNG.java:115)
at org.testng.remote.RemoteTestNG.initAndRun(RemoteTestNG.java:251)
at org.testng.remote.RemoteTestNG.main(RemoteTestNG.java:77)
Caused by: java.lang.AssertionError: expected:<0> but was:<1>
at org.junit.Assert.fail(Assert.java:89)
at org.junit.Assert.failNotEquals(Assert.java:835)
at org.junit.Assert.assertEquals(Assert.java:120)
at org.junit.Assert.assertEquals(Assert.java:146)
at org.junit.internal.ExactComparisonCriteria.assertElementsEqual(ExactComparisonCriteria.java:8)
at org.junit.internal.ComparisonCriteria.arrayEquals(ComparisonCriteria.java:76)
... 33 more
]]>
    </failure>
  </testcase> <!-- test -->
  <system-out/>
</testsuite> <!-- Week5.HomeWork.MoveZeros -->
